Workbook

Sheet Elenco Completo (Hub)
A1: FC ANDORRA (LaLiga Hypermotion) — CENTRAL DE ELENCO (DERIVADA DOS LOGS POR PARTIDA)
A2: Treinador: Carles Manso Rubio | Data: 19/10/2025 | 13J: 9V 4E 0D · 32 GP / 8 GC (Invicto!) | Gols Conciliados: 32 = 32 GP
A4: ID Atleta | B4: Nº Camisa | C4: Jogador | D4: Nome Completo | E4: Hierarquia Escalação (Treinador) | F4: Utilização Real (Derivada) | G4: Papel Contratual | H4: Posição Principal | I4: Posições Secundárias | J4: Setor | K4: Overall (OVR) | L4: Potencial (POT) | M4: Margem de Potencial (POT-OVR) | N4: Evolução Real no Save | O4: Idade | P4: Nascimento | Q4: Nacionalidade | R4: Valor de Mercado (€) | S4: Salário Semanal (€) | T4: Situação Multa Rescisória | U4: Fim Contrato | V4: Alerta Contratual | W4: Jogos (Logs) | X4: Titular (Logs) | Y4: Reserva (Logs) | Z4: Minutos (Logs) | AA4: % Minutos | AB4: Gols (Conciliado Logs) | AC4: Assistências (Bloco stndgs) | AD4: Participações (G+A) | AE4: G+A por 90m | AF4: Gols (Liga) | AG4: Assist. (Liga) | AH4: Gols (Pré-Temp/Copa) | AI4: Assist. (Pré-Temp/Copa) | AJ4: Clean Sheets | AK4: Nota Média (Logs) | AL4: Forma Recente | AM4: Confiança da Amostra | AN4: Recomendação Consultiva (Camada 3) | AO4: Justificativa Numérica | AP4: Descrição Derivada Automática
A5: 262498 | B5: 2 | C5: Álex Petxa | D5: Álex Petxarroman Eizaguirre | E5: Titular (LE) | F5: Titular Efetivo (49% min) | G5: Rodízio | H5: LD | I5: MC | J5: Defesa | K5: 66 | L5: 66 | M5: =L5-K5 -> 0 | N5: =K5-66 -> 0 | O5: 28 | P5: 07/02/1997 | Q5: Espanha | R5: 925000 | S5: 3600 | T5: Sem multa rescisória | U5: 2028 | V5: Seguro (até 2028) | W5: =COUNTIFS('Desempenho por Jogo (Logs)'!$G$5:$G$206, A5) -> 12 | X5: =COUNTIFS('Desempenho por Jogo (Logs)'!$G$5:$G$206, A5, 'Desempenho por Jogo (Logs)'!$J$5:$J$206, "<>RES") -> 7 | Y5: =COUNTIFS('Desempenho por Jogo (Logs)'!$G$5:$G$206, A5, 'Desempenho por Jogo (Logs)'!$J$5:$J$206, "RES") -> 5 | Z5: =SUMIFS('Desempenho por Jogo (Logs)'!$K$5:$K$206, 'Desempenho por Jogo (Logs)'!$G$5:$G$206, A5) -> 574 | AA5: =IF(Z5>0, Z5/540, 0) -> 0.491 | AB5: =SUMIFS('Desempenho por Jogo (Logs)'!$L$5:$L$206, 'Desempenho por Jogo (Logs)'!$G$5:$G$206, A5) -> 0 | AC5: 2 | AD5: =AB5+AC5 -> 2 | AE5: =IF(Z5>0, ROUND((AD5/Z5)*90, 2), 0) -> 0.31 | AF5: =SUMIFS('Desempenho por Jogo (Logs)'!$L$5:$L$206, 'Desempenho por Jogo (Logs)'!$G$5:$G$206, A5, 'Desempenho por Jogo (Logs)'!$C$5:$C$206, "*Liga*") -> 0 | AG5: 2 | AH5: =SUMIFS('Desempenho por Jogo (Logs)'!$L$5:$L$206, 'Desempenho por Jogo (Logs)'!$G$5:$G$206, A5, 'Desempenho por Jogo (Logs)'!$C$5:$C$206, "*Trophy*") -> 0 | AI5: 0 | AJ5: 0 | AK5: =IFERROR(ROUND(AVERAGEIFS('Desempenho por Jogo (Logs)'!$N$5:$N$206, 'Desempenho por Jogo (Logs)'!$G$5:$G$206, A5, 'Desempenho por Jogo (Logs)'!$N$5:$N$206, ">0"), 2), "S/N") -> 7.12 | AL5: Regular (6,72) | AM5: =IF(W5=0, "Nula (0 jogos)", IF(OR(W5<=2, Z5<150), "Baixa — Amostra Insuficiente", IF(AND(W5>=4, Z5>=240), "Alta", "Moderada"))) -> Alta (≥4J e ≥270m) | AN5: =IF(W5=0, "Sem minutagem no save", IF(OR(W5<=2, Z5<150), "Amostra insuficiente (" & W5 & "J / " & Z5 & "m) — Continuar observando", IF(AK5>=7.5, "Promover minutos / Titularidade em ascensão", IF(AK5>=7.0, "Manter minutagem atual", "Avaliar opções / Rotação")))) -> Titular Regular na Temporada — Manter | AO5: Titular com 574 min em 12J (49,1% do tempo possível, Nota 7,12) | AP5: Atleta de 28 anos (Espanha). posição LD (MC). hierarquia atual 'Titular (LE)'. Overall 66 e Potencial 66 (margem de potencial +0; evolução real no save +0). Soma 574 min em 12 partidas (7T/5R). com 0 gol(s) verificado(s) por partida. 2 assistência(s) na temporada (2 G+A) e nota média 7.12. Vínculo: contrato até 2028 (Rodízio). avaliado em € 925.000.
A6: 273022 | B6: 3 | C6: Yeray Cabanzón | D6: Yeray Cabanzón | E6: Titular (PD) | F6: Titular Efetivo (40% min) | G6: Rodízio | H6: MD | I6: PD | J6: Meio-Campo | K6: 67 | L6: 75 | M6: =L6-K6 -> 8 | N6: =K6-66 -> 1 | O6: 22 | P6: 15/05/2003 | Q6: Espanha | R6: 2300000 | S6: 3200 | T6: Sem multa rescisória | U6: 2027 | V6: Atenção: Expira em 2027 (2 anos) | W6: =COUNTIFS('Desempenho por Jogo (Logs)'!$G$5:$G$206, A6) -> 7 | X6: =COUNTIFS('Desempenho por Jogo (Logs)'!$G$5:$G$206, A6, 'Desempenho por Jogo (Logs)'!$J$5:$J$206, "<>RES") -> 6 | Y6: =COUNTIFS('Desempenho por Jogo (Logs)'!$G$5:$G$206, A6, 'Desempenho por Jogo (Logs)'!$J$5:$J$206, "RES") -> 1 | Z6: =SUMIFS('Desempenho por Jogo (Logs)'!$K$5:$K$206, 'Desempenho por Jogo (Logs)'!$G$5:$G$206, A6) -> 463 | AA6: =IF(Z6>0, Z6/540, 0) -> 0.396 | AB6: =SUMIFS('Desempenho por Jogo (Logs)'!$L$5:$L$206, 'Desempenho por Jogo (Logs)'!$G$5:$G$206, A6) -> 3 | AC6: 4 | AD6: =AB6+AC6 -> 7 | AE6: =IF(Z6>0, ROUND((AD6/Z6)*90, 2), 0) -> 1.36 | AF6: =SUMIFS('Desempenho por Jogo (Logs)'!$L$5:$L$206, 'Desempenho por Jogo (Logs)'!$G$5:$G$206, A6, 'Desempenho por Jogo (Logs)'!$C$5:$C$206, "*Liga*") -> 2 | AG6: 4 | AH6: =SUMIFS('Desempenho por Jogo (Logs)'!$L$5:$L$206, 'Desempenho por Jogo (Logs)'!$G$5:$G$206, A6, 'Desempenho por Jogo (Logs)'!$C$5:$C$206, "*Trophy*") -> 1 | AI6: 0 | AJ6: 0 | AK6: =IFERROR(ROUND(AVERAGEIFS('Desempenho por Jogo (Logs)'!$N$5:$N$206, 'Desempenho por Jogo (Logs)'!$G$5:$G$206, A6, 'Desempenho por Jogo (Logs)'!$N$5:$N$206, ">0"), 2), "S/N") -> 7.66 | AL6: Excelente (7,80) | AM6: =IF(W6=0, "Nula (0 jogos)", IF(OR(W6<=2, Z6<150), "Baixa — Amostra Insuficiente", IF(AND(W6>=4, Z6>=240), "Alta", "Moderada"))) -> Alta (≥4J e ≥270m) | AN6: =IF(W6=0, "Sem minutagem no save", IF(OR(W6<=2, Z6<150), "Amostra insuficiente (" & W6 & "J / " & Z6 & "m) — Continuar observando", IF(AK6>=7.5, "Promover minutos / Titularidade em ascensão", IF(AK6>=7.0, "Manter minutagem atual", "Avaliar opções / Rotação")))) -> Titular Regular na Temporada — Manter | AO6: Titular com 463 min em 7J (39,6% do tempo possível, Nota 7,66) | AP6: Atleta de 22 anos (Espanha). posição MD (PD). hierarquia atual 'Titular (PD)'. Overall 67 e Potencial 75 (margem de potencial +8; evolução real no save +1). Soma 463 min em 7 partidas (6T/1R). com 3 gol(s) verificado(s) por partida. 4 assistência(s) na temporada (7 G+A) e nota média 7.66. Vínculo: contrato até 2027 (Rodízio). avaliado em € 2.300.000.
A7: 271955 | B7: 5 | C7: Bomba | D7: Marc Bombardó Poyato | E7: Titular (ZAG) | F7: Titular Efetivo (65% min) | G7: Rodízio | H7: ZAG | I7: — | J7: Defesa | K7: 67 | L7: 78 | M7: =L7-K7 -> 11 | N7: =K7-65 -> 2 | O7: 19 | P7: 24/11/2005 | Q7: Espanha | R7: 1900000 | S7: 2000 | T7: € 4.150.000 | U7: 2027 | V7: Atenção: Expira em 2027 (2 anos) | W7: =COUNTIFS('Desempenho por Jogo (Logs)'!$G$5:$G$206, A7) -> 9 | X7: =COUNTIFS('Desempenho por Jogo (Logs)'!$G$5:$G$206, A7, 'Desempenho por Jogo (Logs)'!$J$5:$J$206, "<>RES") -> 9 | Y7: =COUNTIFS('Desempenho por Jogo (Logs)'!$G$5:$G$206, A7, 'Desempenho por Jogo (Logs)'!$J$5:$J$206, "RES") -> 0 | Z7: =SUMIFS('Desempenho por Jogo (Logs)'!$K$5:$K$206, 'Desempenho por Jogo (Logs)'!$G$5:$G$206, A7) -> 765 | AA7: =IF(Z7>0, Z7/540, 0) -> 0.654 | AB7: =SUMIFS('Desempenho por Jogo (Logs)'!$L$5:$L$206, 'Desempenho por Jogo (Logs)'!$G$5:$G$206, A7) -> 0 | AC7: 0 | AD7: =AB7+AC7 -> 0 | AE7: =IF(Z7>0, ROUND((AD7/Z7)*90, 2), 0) -> 0 | AF7: =SUMIFS('Desempenho por Jogo (Logs)'!$L$5:$L$206, 'Desempenho por Jogo (Logs)'!$G$5:$G$206, A7, 'Desempenho por Jogo (Logs)'!$C$5:$C$206, "*Liga*") -> 0 | AG7: 0 | AH7: =SUMIFS('Desempenho por Jogo (Logs)'!$L$5:$L$206, 'Desempenho por Jogo (Logs)'!$G$5:$G$206, A7, 'Desempenho por Jogo (Logs)'!$C$5:$C$206, "*Trophy*") -> 0 | AI7: 0 | AJ7: 0 | AK7: =IFERROR(ROUND(AVERAGEIFS('Desempenho por Jogo (Logs)'!$N$5:$N$206, 'Desempenho por Jogo (Logs)'!$G$5:$G$206, A7, 'Desempenho por Jogo (Logs)'!$N$5:$N$206, ">0"), 2), "S/N") -> 7.04 | AL7: Boa (7,04) | AM7: =IF(W7=0, "Nula (0 jogos)", IF(OR(W7<=2, Z7<150), "Baixa — Amostra Insuficiente", IF(AND(W7>=4, Z7>=240), "Alta", "Moderada"))) -> Alta (≥4J e ≥270m) | AN7: =IF(W7=0, "Sem minutagem no save", IF(OR(W7<=2, Z7<150), "Amostra insuficiente (" & W7 & "J / " & Z7 & "m) — Continuar observando", IF(AK7>=7.5, "Promover minutos / Titularidade em ascensão", IF(AK7>=7.0, "Manter minutagem atual", "Avaliar opções / Rotação")))) -> Jovem em Desenvolvimento Ativo — Manter Minutagem | AO7: 19 anos, POT 78 (+11 margem) e 765 min disputados (9J) | AP7: Atleta de 19 anos (Espanha). posição ZAG. hierarquia atual 'Titular (ZAG)'. Overall 67 e Potencial 78 (margem de potencial +11; evolução real no save +2). Soma 765 min em 9 partidas (9T/0R). com 0 gol(s) verificado(s) por partida. 0 assistência(s) na temporada (0 G+A) e nota média 7.04. Vínculo: contrato até 2027 (Rodízio). avaliado em € 1.900.000.
A8: 266100 | B8: 6 | C8: Daniel Villahermosa | D8: Daniel Villahermosa | E8: Titular (MC) | F8: Titular Efetivo (60% min) | G8: Rodízio | H8: MC | I8: VOL | J8: Meio-Campo | K8: 68 | L8: 70 | M8: =L8-K8 -> 2 | N8: =K8-67 -> 1 | O8: 24 | P8: 03/01/2001 | Q8: Espanha | R8: 1600000 | S8: 3700 | T8: € 2.600.000 | U8: 2030 | V8: Seguro (até 2030) | W8: =COUNTIFS('Desempenho por Jogo (Logs)'!$G$5:$G$206, A8) -> 10 | X8: =COUNTIFS('Desempenho por Jogo (Logs)'!$G$5:$G$206, A8, 'Desempenho por Jogo (Logs)'!$J$5:$J$206, "<>RES") -> 9 | Y8: =COUNTIFS('Desempenho por Jogo (Logs)'!$G$5:$G$206, A8, 'Desempenho por Jogo (Logs)'!$J$5:$J$206, "RES") -> 1 | Z8: =SUMIFS('Desempenho por Jogo (Logs)'!$K$5:$K$206, 'Desempenho por Jogo (Logs)'!$G$5:$G$206, A8) -> 705 | AA8: =IF(Z8>0, Z8/540, 0) -> 0.603 | AB8: =SUMIFS('Desempenho por Jogo (Logs)'!$L$5:$L$206, 'Desempenho por Jogo (Logs)'!$G$5:$G$206, A8) -> 1 | AC8: 4 | AD8: =AB8+AC8 -> 5 | AE8: =IF(Z8>0, ROUND((AD8/Z8)*90, 2), 0) -> 0.64 | AF8: =SUMIFS('Desempenho por Jogo (Logs)'!$L$5:$L$206, 'Desempenho por Jogo (Logs)'!$G$5:$G$206, A8, 'Desempenho por Jogo (Logs)'!$C$5:$C$206, "*Liga*") -> 0 | AG8: 3 | AH8: =SUMIFS('Desempenho por Jogo (Logs)'!$L$5:$L$206, 'Desempenho por Jogo (Logs)'!$G$5:$G$206, A8, 'Desempenho por Jogo (Logs)'!$C$5:$C$206, "*Trophy*") -> 1 | AI8: 1 | AJ8: 1 | AK8: =IFERROR(ROUND(AVERAGEIFS('Desempenho por Jogo (Logs)'!$N$5:$N$206, 'Desempenho por Jogo (Logs)'!$G$5:$G$206, A8, 'Desempenho por Jogo (Logs)'!$N$5:$N$206, ">0"), 2), "S/N") -> 7.23 | AL8: Boa (7,00) | AM8: =IF(W8=0, "Nula (0 jogos)", IF(OR(W8<=2, Z8<150), "Baixa — Amostra Insuficiente", IF(AND(W8>=4, Z8>=240), "Alta", "Moderada"))) -> Alta (≥4J e ≥270m) | AN8: =IF(W8=0, "Sem minutagem no save", IF(OR(W8<=2, Z8<150), "Amostra insuficiente (" & W8 & "J / " & Z8 & "m) — Continuar observando", IF(AK8>=7.5, "Promover minutos / Titularidade em ascensão", IF(AK8>=7.0, "Manter minutagem atual", "Avaliar opções / Rotação")))) -> Titular Regular na Temporada — Manter | AO8: Titular com 705 min em 10J (60,3% do tempo possível, Nota 7,23) | AP8: Atleta de 24 anos (Espanha). posição MC (VOL). hierarquia atual 'Titular (MC)'. Overall 68 e Potencial 70 (margem de potencial +2; evolução real no save +1). Soma 705 min em 10 partidas (9T/1R). com 1 gol(s) verificado(s) por partida. 4 assistência(s) na temporada (5 G+A) e nota média 7.23. Vínculo: contrato até 2030 (Rodízio). avaliado em € 1.600.000.
A9: 275520 | B9: 8 | C9: Manu Bueno | D9: Manuel Bueno Sebastián | E9: Titular (MC) | F9: Titular Efetivo (43% min) | G9: Importante | H9: MC | I9: MEI, VOL | J9: Meio-Campo | K9: 67 | L9: 76 | M9: =L9-K9 -> 9 | N9: =K9-67 -> 0 | O9: 21 | P9: 28/07/2004 | Q9: Espanha | R9: 2700000 | S9: 10000 | T9: € 6.600.000 | U9: 2029 | V9: Seguro (até 2029) | W9: =COUNTIFS('Desempenho por Jogo (Logs)'!$G$5:$G$206, A9) -> 8 | X9: =COUNTIFS('Desempenho por Jogo (Logs)'!$G$5:$G$206, A9, 'Desempenho por Jogo (Logs)'!$J$5:$J$206, "<>RES") -> 7 | Y9: =COUNTIFS('Desempenho por Jogo (Logs)'!$G$5:$G$206, A9, 'Desempenho por Jogo (Logs)'!$J$5:$J$206, "RES") -> 1 | Z9: =SUMIFS('Desempenho por Jogo (Logs)'!$K$5:$K$206, 'Desempenho por Jogo (Logs)'!$G$5:$G$206, A9) -> 502 | AA9: =IF(Z9>0, Z9/540, 0) -> 0.429 | AB9: =SUMIFS('Desempenho por Jogo (Logs)'!$L$5:$L$206, 'Desempenho por Jogo (Logs)'!$G$5:$G$206, A9) -> 2 | AC9: 1 | AD9: =AB9+AC9 -> 3 | AE9: =IF(Z9>0, ROUND((AD9/Z9)*90, 2), 0) -> 0.54 | AF9: =SUMIFS('Desempenho por Jogo (Logs)'!$L$5:$L$206, 'Desempenho por Jogo (Logs)'!$G$5:$G$206, A9, 'Desempenho por Jogo (Logs)'!$C$5:$C$206, "*Liga*") -> 2 | AG9: 1 | AH9: =SUMIFS('Desempenho por Jogo (Logs)'!$L$5:$L$206, 'Desempenho por Jogo (Logs)'!$G$5:$G$206, A9, 'Desempenho por Jogo (Logs)'!$C$5:$C$206, "*Trophy*") -> 0 | AI9: 0 | AJ9: 0 | AK9: =IFERROR(ROUND(AVERAGEIFS('Desempenho por Jogo (Logs)'!$N$5:$N$206, 'Desempenho por Jogo (Logs)'!$G$5:$G$206, A9, 'Desempenho por Jogo (Logs)'!$N$5:$N$206, ">0"), 2), "S/N") -> 6.89 | AL9: Boa (7,02) | AM9: =IF(W9=0, "Nula (0 jogos)", IF(OR(W9<=2, Z9<150), "Baixa — Amostra Insuficiente", IF(AND(W9>=4, Z9>=240), "Alta", "Moderada"))) -> Alta (≥4J e ≥270m) | AN9: =IF(W9=0, "Sem minutagem no save", IF(OR(W9<=2, Z9<150), "Amostra insuficiente (" & W9 & "J / " & Z9 & "m) — Continuar observando", IF(AK9>=7.5, "Promover minutos / Titularidade em ascensão", IF(AK9>=7.0, "Manter minutagem atual", "Avaliar opções / Rotação")))) -> Titular Regular na Temporada — Manter | AO9: Titular com 502 min em 8J (42,9% do tempo possível, Nota 6,89) | AP9: Atleta de 21 anos (Espanha). posição MC (MEI. VOL). hierarquia atual 'Titular (MC)'. Overall 67 e Potencial 76 (margem de potencial +9; evolução real no save +0). Soma 502 min em 8 partidas (7T/1R). com 2 gol(s) verificado(s) por partida. 1 assistência(s) na temporada (3 G+A) e nota média 6.89. Vínculo: contrato até 2029 (Importante). avaliado em € 2.700.000.
A10: 247500 | B10: 12 | C10: Edgar González | D10: Edgar González Estrada | E10: Titular (ZAG) | F10: Titular Efetivo (80% min) | G10: Rodízio | H10: ZAG | I10: — | J10: Defesa | K10: 72 | L10: 72 | M10: =L10-K10 -> 0 | N10: =K10-71 -> 1 | O10: 28 | P10: 02/04/1997 | Q10: Espanha | R10: 2100000 | S10: 6900 | T10: Sem multa rescisória | U10: 2028 | V10: Seguro (até 2028) | W10: =COUNTIFS('Desempenho por Jogo (Logs)'!$G$5:$G$206, A10) -> 11 | X10: =COUNTIFS('Desempenho por Jogo (Logs)'!$G$5:$G$206, A10, 'Desempenho por Jogo (Logs)'!$J$5:$J$206, "<>RES") -> 11 | Y10: =COUNTIFS('Desempenho por Jogo (Logs)'!$G$5:$G$206, A10, 'Desempenho por Jogo (Logs)'!$J$5:$J$206, "RES") -> 0 | Z10: =SUMIFS('Desempenho por Jogo (Logs)'!$K$5:$K$206, 'Desempenho por Jogo (Logs)'!$G$5:$G$206, A10) -> 930 | AA10: =IF(Z10>0, Z10/540, 0) -> 0.795 | AB10: =SUMIFS('Desempenho por Jogo (Logs)'!$L$5:$L$206, 'Desempenho por Jogo (Logs)'!$G$5:$G$206, A10) -> 0 | AC10: 0 | AD10: =AB10+AC10 -> 0 | AE10: =IF(Z10>0, ROUND((AD10/Z10)*90, 2), 0) -> 0 | AF10: =SUMIFS('Desempenho por Jogo (Logs)'!$L$5:$L$206, 'Desempenho por Jogo (Logs)'!$G$5:$G$206, A10, 'Desempenho por Jogo (Logs)'!$C$5:$C$206, "*Liga*") -> 0 | AG10: 0 | AH10: =SUMIFS('Desempenho por Jogo (Logs)'!$L$5:$L$206, 'Desempenho por Jogo (Logs)'!$G$5:$G$206, A10, 'Desempenho por Jogo (Logs)'!$C$5:$C$206, "*Trophy*") -> 0 | AI10: 0 | AJ10: 0 | AK10: =IFERROR(ROUND(AVERAGEIFS('Desempenho por Jogo (Logs)'!$N$5:$N$206, 'Desempenho por Jogo (Logs)'!$G$5:$G$206, A10, 'Desempenho por Jogo (Logs)'!$N$5:$N$206, ">0"), 2), "S/N") -> 6.84 | AL10: Regular (6,80) | AM10: =IF(W10=0, "Nula (0 jogos)", IF(OR(W10<=2, Z10<150), "Baixa — Amostra Insuficiente", IF(AND(W10>=4, Z10>=240), "Alta", "Moderada"))) -> Alta (≥4J e ≥270m) | AN10: =IF(W10=0, "Sem minutagem no save", IF(OR(W10<=2, Z10<150), "Amostra insuficiente (" & W10 & "J / " & Z10 & "m) — Continuar observando", IF(AK10>=7.5, "Promover minutos / Titularidade em ascensão", IF(AK10>=7.0, "Manter minutagem atual", "Avaliar opções / Rotação")))) -> Titular Regular na Temporada — Manter | AO10: Titular com 930 min em 11J (79,5% do tempo possível, Nota 6,84) | AP10: Atleta de 28 anos (Espanha). posição ZAG. hierarquia atual 'Titular (ZAG)'. Overall 72 e Potencial 72 (margem de potencial +0; evolução real no save +1). Soma 930 min em 11 partidas (11T/0R). com 0 gol(s) verificado(s) por partida. 0 assistência(s) na temporada (0 G+A) e nota média 6.84. Vínculo: contrato até 2028 (Rodízio). avaliado em € 2.100.000.
A11: 278758 | B11: 16 | C11: Jastin | D11: Jastin García | E11: Titular (PE) | F11: Titular Efetivo (54% min) | G11: Rodízio | H11: ME | I11: PE | J11: Meio-Campo | K11: 69 | L11: 80 | M11: =L11-K11 -> 11 | N11: =K11-68 -> 1 | O11: 21 | P11: 16/01/2004 | Q11: Espanha | R11: 3500000 | S11: 3600 | T11: Emprestado (Sem multa) | U11: 2027 | V11: Empréstimo até Jun/2026 | W11: =COUNTIFS('Desempenho por Jogo (Logs)'!$G$5:$G$206, A11) -> 12 | X11: =COUNTIFS('Desempenho por Jogo (Logs)'!$G$5:$G$206, A11, 'Desempenho por Jogo (Logs)'!$J$5:$J$206, "<>RES") -> 7 | Y11: =COUNTIFS('Desempenho por Jogo (Logs)'!$G$5:$G$206, A11, 'Desempenho por Jogo (Logs)'!$J$5:$J$206, "RES") -> 5 | Z11: =SUMIFS('Desempenho por Jogo (Logs)'!$K$5:$K$206, 'Desempenho por Jogo (Logs)'!$G$5:$G$206, A11) -> 626 | AA11: =IF(Z11>0, Z11/540, 0) -> 0.535 | AB11: =SUMIFS('Desempenho por Jogo (Logs)'!$L$5:$L$206, 'Desempenho por Jogo (Logs)'!$G$5:$G$206, A11) -> 0 | AC11: 4 | AD11: =AB11+AC11 -> 4 | AE11: =IF(Z11>0, ROUND((AD11/Z11)*90, 2), 0) -> 0.58 | AF11: =SUMIFS('Desempenho por Jogo (Logs)'!$L$5:$L$206, 'Desempenho por Jogo (Logs)'!$G$5:$G$206, A11, 'Desempenho por Jogo (Logs)'!$C$5:$C$206, "*Liga*") -> 0 | AG11: 4 | AH11: =SUMIFS('Desempenho por Jogo (Logs)'!$L$5:$L$206, 'Desempenho por Jogo (Logs)'!$G$5:$G$206, A11, 'Desempenho por Jogo (Logs)'!$C$5:$C$206, "*Trophy*") -> 0 | AI11: 0 | AJ11: 1 | AK11: =IFERROR(ROUND(AVERAGEIFS('Desempenho por Jogo (Logs)'!$N$5:$N$206, 'Desempenho por Jogo (Logs)'!$G$5:$G$206, A11, 'Desempenho por Jogo (Logs)'!$N$5:$N$206, ">0"), 2), "S/N") -> 7.28 | AL11: Boa (7,14) | AM11: =IF(W11=0, "Nula (0 jogos)", IF(OR(W11<=2, Z11<150), "Baixa — Amostra Insuficiente", IF(AND(W11>=4, Z11>=240), "Alta", "Moderada"))) -> Alta (≥4J e ≥270m) | AN11: =IF(W11=0, "Sem minutagem no save", IF(OR(W11<=2, Z11<150), "Amostra insuficiente (" & W11 & "J / " & Z11 & "m) — Continuar observando", IF(AK11>=7.5, "Promover minutos / Titularidade em ascensão", IF(AK11>=7.0, "Manter minutagem atual", "Avaliar opções / Rotação")))) -> Jovem em Desenvolvimento Ativo — Manter Minutagem | AO11: 21 anos, POT 80 (+11 margem) e 626 min disputados (12J) | AP11: Atleta de 21 anos (Espanha). posição ME (PE). hierarquia atual 'Titular (PE)'. Overall 69 e Potencial 80 (margem de potencial +11; evolução real no save +1). Soma 626 min em 12 partidas (7T/5R). com 0 gol(s) verificado(s) por partida. 4 assistência(s) na temporada (4 G+A) e nota média 7.28. Vínculo: atleta emprestado ao clube até 2026. avaliado em € 3.500.000.
A12: 263006 | B12: 19 | C12: Imanol | D12: Imanol García de Albéniz | E12: Titular (LD) | F12: Titular Efetivo (57% min) | G12: Rodízio | H12: LE | I12: ME | J12: Defesa | K12: 71 | L12: 73 | M12: =L12-K12 -> 2 | N12: =K12-70 -> 1 | O12: 25 | P12: 09/06/2000 | Q12: Espanha | R12: 2300000 | S12: 5600 | T12: Sem multa rescisória | U12: 2029 | V12: Seguro (até 2029) | W12: =COUNTIFS('Desempenho por Jogo (Logs)'!$G$5:$G$206, A12) -> 11 | X12: =COUNTIFS('Desempenho por Jogo (Logs)'!$G$5:$G$206, A12, 'Desempenho por Jogo (Logs)'!$J$5:$J$206, "<>RES") -> 10 | Y12: =COUNTIFS('Desempenho por Jogo (Logs)'!$G$5:$G$206, A12, 'Desempenho por Jogo (Logs)'!$J$5:$J$206, "RES") -> 1 | Z12: =SUMIFS('Desempenho por Jogo (Logs)'!$K$5:$K$206, 'Desempenho por Jogo (Logs)'!$G$5:$G$206, A12) -> 669 | AA12: =IF(Z12>0, Z12/540, 0) -> 0.572 | AB12: =SUMIFS('Desempenho por Jogo (Logs)'!$L$5:$L$206, 'Desempenho por Jogo (Logs)'!$G$5:$G$206, A12) -> 1 | AC12: 2 | AD12: =AB12+AC12 -> 3 | AE12: =IF(Z12>0, ROUND((AD12/Z12)*90, 2), 0) -> 0.4 | AF12: =SUMIFS('Desempenho por Jogo (Logs)'!$L$5:$L$206, 'Desempenho por Jogo (Logs)'!$G$5:$G$206, A12, 'Desempenho por Jogo (Logs)'!$C$5:$C$206, "*Liga*") -> 0 | AG12: 2 | AH12: =SUMIFS('Desempenho por Jogo (Logs)'!$L$5:$L$206, 'Desempenho por Jogo (Logs)'!$G$5:$G$206, A12, 'Desempenho por Jogo (Logs)'!$C$5:$C$206, "*Trophy*") -> 1 | AI12: 0 | AJ12: 0 | AK12: =IFERROR(ROUND(AVERAGEIFS('Desempenho por Jogo (Logs)'!$N$5:$N$206, 'Desempenho por Jogo (Logs)'!$G$5:$G$206, A12, 'Desempenho por Jogo (Logs)'!$N$5:$N$206, ">0"), 2), "S/N") -> 6.9 | AL12: Regular (6,64) | AM12: =IF(W12=0, "Nula (0 jogos)", IF(OR(W12<=2, Z12<150), "Baixa — Amostra Insuficiente", IF(AND(W12>=4, Z12>=240), "Alta", "Moderada"))) -> Alta (≥4J e ≥270m) | AN12: =IF(W12=0, "Sem minutagem no save", IF(OR(W12<=2, Z12<150), "Amostra insuficiente (" & W12 & "J / " & Z12 & "m) — Continuar observando", IF(AK12>=7.5, "Promover minutos / Titularidade em ascensão", IF(AK12>=7.0, "Manter minutagem atual", "Avaliar opções / Rotação")))) -> Titular Regular na Temporada — Manter | AO12: Titular com 669 min em 11J (57,2% do tempo possível, Nota 6,90) | AP12: Atleta de 25 anos (Espanha). posição LE (ME). hierarquia atual 'Titular (LD)'. Overall 71 e Potencial 73 (margem de potencial +2; evolução real no save +1). Soma 669 min em 11 partidas (10T/1R). com 1 gol(s) verificado(s) por partida. 2 assistência(s) na temporada (3 G+A) e nota média 6.90. Vínculo: contrato até 2029 (Rodízio). avaliado em € 2.300.000.
A13: 279881 | B13: 21 | C13: Efe Akman | D13: Efe Akman | E13: Titular (MC) | F13: Titular Efetivo (63% min) | G13: Rodízio | H13: MC | I13: VOL | J13: Meio-Campo | K13: 65 | L13: 78 | M13: =L13-K13 -> 13 | N13: =K13-64 -> 1 | O13: 19 | P13: 21/03/2006 | Q13: Turquia | R13: 1600000 | S13: 1900 | T13: € 3.500.000 | U13: 2029 | V13: Seguro (até 2029) | W13: =COUNTIFS('Desempenho por Jogo (Logs)'!$G$5:$G$206, A13) -> 9 | X13: =COUNTIFS('Desempenho por Jogo (Logs)'!$G$5:$G$206, A13, 'Desempenho por Jogo (Logs)'!$J$5:$J$206, "<>RES") -> 9 | Y13: =COUNTIFS('Desempenho por Jogo (Logs)'!$G$5:$G$206, A13, 'Desempenho por Jogo (Logs)'!$J$5:$J$206, "RES") -> 0 | Z13: =SUMIFS('Desempenho por Jogo (Logs)'!$K$5:$K$206, 'Desempenho por Jogo (Logs)'!$G$5:$G$206, A13) -> 735 | AA13: =IF(Z13>0, Z13/540, 0) -> 0.628 | AB13: =SUMIFS('Desempenho por Jogo (Logs)'!$L$5:$L$206, 'Desempenho por Jogo (Logs)'!$G$5:$G$206, A13) -> 0 | AC13: 3 | AD13: =AB13+AC13 -> 3 | AE13: =IF(Z13>0, ROUND((AD13/Z13)*90, 2), 0) -> 0.37 | AF13: =SUMIFS('Desempenho por Jogo (Logs)'!$L$5:$L$206, 'Desempenho por Jogo (Logs)'!$G$5:$G$206, A13, 'Desempenho por Jogo (Logs)'!$C$5:$C$206, "*Liga*") -> 0 | AG13: 2 | AH13: =SUMIFS('Desempenho por Jogo (Logs)'!$L$5:$L$206, 'Desempenho por Jogo (Logs)'!$G$5:$G$206, A13, 'Desempenho por Jogo (Logs)'!$C$5:$C$206, "*Trophy*") -> 0 | AI13: 1 | AJ13: 0 | AK13: =IFERROR(ROUND(AVERAGEIFS('Desempenho por Jogo (Logs)'!$N$5:$N$206, 'Desempenho por Jogo (Logs)'!$G$5:$G$206, A13, 'Desempenho por Jogo (Logs)'!$N$5:$N$206, ">0"), 2), "S/N") -> 7.82 | AL13: Boa (7,00) | AM13: =IF(W13=0, "Nula (0 jogos)", IF(OR(W13<=2, Z13<150), "Baixa — Amostra Insuficiente", IF(AND(W13>=4, Z13>=240), "Alta", "Moderada"))) -> Alta (≥4J e ≥270m) | AN13: =IF(W13=0, "Sem minutagem no save", IF(OR(W13<=2, Z13<150), "Amostra insuficiente (" & W13 & "J / " & Z13 & "m) — Continuar observando", IF(AK13>=7.5, "Promover minutos / Titularidade em ascensão", IF(AK13>=7.0, "Manter minutagem atual", "Avaliar opções / Rotação")))) -> Jovem em Desenvolvimento Ativo — Manter Minutagem | AO13: 19 anos, POT 78 (+13 margem) e 735 min disputados (9J) | AP13: Atleta de 19 anos (Turquia). posição MC (VOL). hierarquia atual 'Titular (MC)'. Overall 65 e Potencial 78 (margem de potencial +13; evolução real no save +1). Soma 735 min em 9 partidas (9T/0R). com 0 gol(s) verificado(s) por partida. 3 assistência(s) na temporada (3 G+A) e nota média 7.82. Vínculo: contrato até 2029 (Rodízio). avaliado em € 1.600.000.
A14: 236393 | B14: 22 | C14: Marc Cardona | D14: Marc Cardona Rovira | E14: Titular (ATA) | F14: Titular Efetivo (54% min) | G14: Rodízio | H14: ATA | I14: MD | J14: Ataque | K14: 67 | L14: 67 | M14: =L14-K14 -> 0 | N14: =K14-67 -> 0 | O14: 30 | P14: 09/07/1995 | Q14: Espanha | R14: 1200000 | S14: 4800 | T14: Sem multa rescisória | U14: 2028 | V14: Seguro (até 2028) | W14: =COUNTIFS('Desempenho por Jogo (Logs)'!$G$5:$G$206, A14) -> 9 | X14: =COUNTIFS('Desempenho por Jogo (Logs)'!$G$5:$G$206, A14, 'Desempenho por Jogo (Logs)'!$J$5:$J$206, "<>RES") -> 7 | Y14: =COUNTIFS('Desempenho por Jogo (Logs)'!$G$5:$G$206, A14, 'Desempenho por Jogo (Logs)'!$J$5:$J$206, "RES") -> 2 | Z14: =SUMIFS('Desempenho por Jogo (Logs)'!$K$5:$K$206, 'Desempenho por Jogo (Logs)'!$G$5:$G$206, A14) -> 637 | AA14: =IF(Z14>0, Z14/540, 0) -> 0.544 | AB14: =SUMIFS('Desempenho por Jogo (Logs)'!$L$5:$L$206, 'Desempenho por Jogo (Logs)'!$G$5:$G$206, A14) -> 15 | AC14: 1 | AD14: =AB14+AC14 -> 16 | AE14: =IF(Z14>0, ROUND((AD14/Z14)*90, 2), 0) -> 2.26 | AF14: =SUMIFS('Desempenho por Jogo (Logs)'!$L$5:$L$206, 'Desempenho por Jogo (Logs)'!$G$5:$G$206, A14, 'Desempenho por Jogo (Logs)'!$C$5:$C$206, "*Liga*") -> 15 | AG14: 0 | AH14: =SUMIFS('Desempenho por Jogo (Logs)'!$L$5:$L$206, 'Desempenho por Jogo (Logs)'!$G$5:$G$206, A14, 'Desempenho por Jogo (Logs)'!$C$5:$C$206, "*Trophy*") -> 0 | AI14: 1 | AJ14: 3 | AK14: =IFERROR(ROUND(AVERAGEIFS('Desempenho por Jogo (Logs)'!$N$5:$N$206, 'Desempenho por Jogo (Logs)'!$G$5:$G$206, A14, 'Desempenho por Jogo (Logs)'!$N$5:$N$206, ">0"), 2), "S/N") -> 8.27 | AL14: Excelente (8,34) | AM14: =IF(W14=0, "Nula (0 jogos)", IF(OR(W14<=2, Z14<150), "Baixa — Amostra Insuficiente", IF(AND(W14>=4, Z14>=240), "Alta", "Moderada"))) -> Alta (≥4J e ≥270m) | AN14: =IF(W14=0, "Sem minutagem no save", IF(OR(W14<=2, Z14<150), "Amostra insuficiente (" & W14 & "J / " & Z14 & "m) — Continuar observando", IF(AK14>=7.5, "Promover minutos / Titularidade em ascensão", IF(AK14>=7.0, "Manter minutagem atual", "Avaliar opções / Rotação")))) -> Titular Regular na Temporada — Manter | AO14: Titular com 637 min em 9J (54,4% do tempo possível, Nota 8,27) | AP14: Atleta de 30 anos (Espanha). posição ATA (MD). hierarquia atual 'Titular (ATA)'. Overall 67 e Potencial 67 (margem de potencial +0; evolução real no save +0). Soma 637 min em 9 partidas (7T/2R). com 15 gol(s) verificado(s) por partida. 1 assistência(s) na temporada (16 G+A) e nota média 8.27. Vínculo: contrato até 2028 (Rodízio). avaliado em € 1.200.000.
A15: 276198 | B15: 25 | C15: Áron Yaakobishvili | D15: Áron Yaakobishvili | E15: Titular (GOL) | F15: Titular Efetivo (62% min) | G15: Rodízio | H15: GOL | I15: — | J15: Goleiro | K15: 72 | L15: 82 | M15: =L15-K15 -> 10 | N15: =K15-70 -> 2 | O15: 19 | P15: 07/03/2006 | Q15: Hungria | R15: 3900000 | S15: 1900 | T15: Emprestado (Sem multa) | U15: 2028 | V15: Empréstimo até Jun/2026 | W15: =COUNTIFS('Desempenho por Jogo (Logs)'!$G$5:$G$206, A15) -> 8 | X15: =COUNTIFS('Desempenho por Jogo (Logs)'!$G$5:$G$206, A15, 'Desempenho por Jogo (Logs)'!$J$5:$J$206, "<>RES") -> 8 | Y15: =COUNTIFS('Desempenho por Jogo (Logs)'!$G$5:$G$206, A15, 'Desempenho por Jogo (Logs)'!$J$5:$J$206, "RES") -> 0 | Z15: =SUMIFS('Desempenho por Jogo (Logs)'!$K$5:$K$206, 'Desempenho por Jogo (Logs)'!$G$5:$G$206, A15) -> 720 | AA15: =IF(Z15>0, Z15/540, 0) -> 0.615 | AB15: =SUMIFS('Desempenho por Jogo (Logs)'!$L$5:$L$206, 'Desempenho por Jogo (Logs)'!$G$5:$G$206, A15) -> 0 | AC15: 0 | AD15: =AB15+AC15 -> 0 | AE15: =IF(Z15>0, ROUND((AD15/Z15)*90, 2), 0) -> 0 | AF15: =SUMIFS('Desempenho por Jogo (Logs)'!$L$5:$L$206, 'Desempenho por Jogo (Logs)'!$G$5:$G$206, A15, 'Desempenho por Jogo (Logs)'!$C$5:$C$206, "*Liga*") -> 0 | AG15: 0 | AH15: =SUMIFS('Desempenho por Jogo (Logs)'!$L$5:$L$206, 'Desempenho por Jogo (Logs)'!$G$5:$G$206, A15, 'Desempenho por Jogo (Logs)'!$C$5:$C$206, "*Trophy*") -> 0 | AI15: 0 | AJ15: 1 | AK15: =IFERROR(ROUND(AVERAGEIFS('Desempenho por Jogo (Logs)'!$N$5:$N$206, 'Desempenho por Jogo (Logs)'!$G$5:$G$206, A15, 'Desempenho por Jogo (Logs)'!$N$5:$N$206, ">0"), 2), "S/N") -> 6.84 | AL15: Regular (6,60) | AM15: =IF(W15=0, "Nula (0 jogos)", IF(OR(W15<=2, Z15<150), "Baixa — Amostra Insuficiente", IF(AND(W15>=4, Z15>=240), "Alta", "Moderada"))) -> Alta (≥4J e ≥270m) | AN15: =IF(W15=0, "Sem minutagem no save", IF(OR(W15<=2, Z15<150), "Amostra insuficiente (" & W15 & "J / " & Z15 & "m) — Continuar observando", IF(AK15>=7.5, "Promover minutos / Titularidade em ascensão", IF(AK15>=7.0, "Manter minutagem atual", "Avaliar opções / Rotação")))) -> Jovem em Desenvolvimento Ativo — Manter Minutagem | AO15: 19 anos, POT 82 (+10 margem) e 720 min disputados (8J) | AP15: Atleta de 19 anos (Hungria). posição GOL. hierarquia atual 'Titular (GOL)'. Overall 72 e Potencial 82 (margem de potencial +10; evolução real no save +2). Soma 720 min em 8 partidas (8T/0R). com 0 gol(s) verificado(s) por partida. 0 assistência(s) na temporada (0 G+A) e nota média 6.84. Vínculo: atleta emprestado ao clube até 2026. avaliado em € 3.900.000.
A16: 79703 | B16: 4 | C16: Gaël Alonso | D16: Gaël Alonso Moreno | E16: Suplente (Banco) | F16: Rotação Ativa (24% min) | G16: Rodízio | H16: ZAG | I16: — | J16: Defesa | K16: 67 | L16: 74 | M16: =L16-K16 -> 7 | N16: =K16-66 -> 1 | O16: 23 | P16: 23/07/2002 | Q16: Espanha | R16: 2100000 | S16: 3000 | T16: Sem multa rescisória | U16: 2028 | V16: Seguro (até 2028) | W16: =COUNTIFS('Desempenho por Jogo (Logs)'!$G$5:$G$206, A16) -> 5 | X16: =COUNTIFS('Desempenho por Jogo (Logs)'!$G$5:$G$206, A16, 'Desempenho por Jogo (Logs)'!$J$5:$J$206, "<>RES") -> 4 | Y16: =COUNTIFS('Desempenho por Jogo (Logs)'!$G$5:$G$206, A16, 'Desempenho por Jogo (Logs)'!$J$5:$J$206, "RES") -> 1 | Z16: =SUMIFS('Desempenho por Jogo (Logs)'!$K$5:$K$206, 'Desempenho por Jogo (Logs)'!$G$5:$G$206, A16) -> 286 | AA16: =IF(Z16>0, Z16/540, 0) -> 0.244 | AB16: =SUMIFS('Desempenho por Jogo (Logs)'!$L$5:$L$206, 'Desempenho por Jogo (Logs)'!$G$5:$G$206, A16) -> 0 | AC16: 0 | AD16: =AB16+AC16 -> 0 | AE16: =IF(Z16>0, ROUND((AD16/Z16)*90, 2), 0) -> 0 | AF16: =SUMIFS('Desempenho por Jogo (Logs)'!$L$5:$L$206, 'Desempenho por Jogo (Logs)'!$G$5:$G$206, A16, 'Desempenho por Jogo (Logs)'!$C$5:$C$206, "*Liga*") -> 0 | AG16: 0 | AH16: =SUMIFS('Desempenho por Jogo (Logs)'!$L$5:$L$206, 'Desempenho por Jogo (Logs)'!$G$5:$G$206, A16, 'Desempenho por Jogo (Logs)'!$C$5:$C$206, "*Trophy*") -> 0 | AI16: 0 | AJ16: 0 | AK16: =IFERROR(ROUND(AVERAGEIFS('Desempenho por Jogo (Logs)'!$N$5:$N$206, 'Desempenho por Jogo (Logs)'!$G$5:$G$206, A16, 'Desempenho por Jogo (Logs)'!$N$5:$N$206, ">0"), 2), "S/N") -> 6.18 | AL16: Oscilante (6,18) | AM16: =IF(W16=0, "Nula (0 jogos)", IF(OR(W16<=2, Z16<150), "Baixa — Amostra Insuficiente", IF(AND(W16>=4, Z16>=240), "Alta", "Moderada"))) -> Alta (≥4J e ≥270m) | AN16: =IF(W16=0, "Sem minutagem no save", IF(OR(W16<=2, Z16<150), "Amostra insuficiente (" & W16 & "J / " & Z16 & "m) — Continuar observando", IF(AK16>=7.5, "Promover minutos / Titularidade em ascensão", IF(AK16>=7.0, "Manter minutagem atual", "Avaliar opções / Rotação")))) -> Manter na Rotação do Elenco | AO16: Participação regular na rotação (286 min em 5J, OVR 67) | AP16: Atleta de 23 anos (Espanha). posição ZAG. hierarquia atual 'Suplente (Banco)'. Overall 67 e Potencial 74 (margem de potencial +7; evolução real no save +1). Soma 286 min em 5 partidas (4T/1R). com 0 gol(s) verificado(s) por partida. 0 assistência(s) na temporada (0 G+A) e nota média 6.18. Vínculo: contrato até 2028 (Rodízio). avaliado em € 2.100.000.
A17: 265405 | B17: 13 | C17: Jesús Owono | D17: Jesús Lázaro Owono Ngua Akeng | E17: Suplente (Banco) | F17: Titular Efetivo (38% min) | G17: Rodízio | H17: GOL | I17: — | J17: Goleiro | K17: 68 | L17: 73 | M17: =L17-K17 -> 5 | N17: =K17-67 -> 1 | O17: 24 | P17: 02/03/2001 | Q17: Guiné Equatorial | R17: 1500000 | S17: 2000 | T17: Sem multa rescisória | U17: 2029 | V17: Seguro (até 2029) | W17: =COUNTIFS('Desempenho por Jogo (Logs)'!$G$5:$G$206, A17) -> 5 | X17: =COUNTIFS('Desempenho por Jogo (Logs)'!$G$5:$G$206, A17, 'Desempenho por Jogo (Logs)'!$J$5:$J$206, "<>RES") -> 5 | Y17: =COUNTIFS('Desempenho por Jogo (Logs)'!$G$5:$G$206, A17, 'Desempenho por Jogo (Logs)'!$J$5:$J$206, "RES") -> 0 | Z17: =SUMIFS('Desempenho por Jogo (Logs)'!$K$5:$K$206, 'Desempenho por Jogo (Logs)'!$G$5:$G$206, A17) -> 450 | AA17: =IF(Z17>0, Z17/540, 0) -> 0.385 | AB17: =SUMIFS('Desempenho por Jogo (Logs)'!$L$5:$L$206, 'Desempenho por Jogo (Logs)'!$G$5:$G$206, A17) -> 0 | AC17: 0 | AD17: =AB17+AC17 -> 0 | AE17: =IF(Z17>0, ROUND((AD17/Z17)*90, 2), 0) -> 0 | AF17: =SUMIFS('Desempenho por Jogo (Logs)'!$L$5:$L$206, 'Desempenho por Jogo (Logs)'!$G$5:$G$206, A17, 'Desempenho por Jogo (Logs)'!$C$5:$C$206, "*Liga*") -> 0 | AG17: 0 | AH17: =SUMIFS('Desempenho por Jogo (Logs)'!$L$5:$L$206, 'Desempenho por Jogo (Logs)'!$G$5:$G$206, A17, 'Desempenho por Jogo (Logs)'!$C$5:$C$206, "*Trophy*") -> 0 | AI17: 0 | AJ17: 0 | AK17: =IFERROR(ROUND(AVERAGEIFS('Desempenho por Jogo (Logs)'!$N$5:$N$206, 'Desempenho por Jogo (Logs)'!$G$5:$G$206, A17, 'Desempenho por Jogo (Logs)'!$N$5:$N$206, ">0"), 2), "S/N") -> 6.6 | AL17: Regular (6,60) | AM17: =IF(W17=0, "Nula (0 jogos)", IF(OR(W17<=2, Z17<150), "Baixa — Amostra Insuficiente", IF(AND(W17>=4, Z17>=240), "Alta", "Moderada"))) -> Alta (≥4J e ≥270m) | AN17: =IF(W17=0, "Sem minutagem no save", IF(OR(W17<=2, Z17<150), "Amostra insuficiente (" & W17 & "J / " & Z17 & "m) — Continuar observando", IF(AK17>=7.5, "Promover minutos / Titularidade em ascensão", IF(AK17>=7.0, "Manter minutagem atual", "Avaliar opções / Rotação")))) -> Manter na Rotação do Elenco | AO17: Participação regular na rotação (450 min em 5J, OVR 68) | AP17: Atleta de 24 anos (Guiné Equatorial). posição GOL. hierarquia atual 'Suplente (Banco)'. Overall 68 e Potencial 73 (margem de potencial +5; evolução real no save +1). Soma 450 min em 5 partidas (5T/0R). com 0 gol(s) verificado(s) por partida. 0 assistência(s) na temporada (0 G+A) e nota média 6.60. Vínculo: contrato até 2029 (Rodízio). avaliado em € 1.500.000.
A18: 230134 | B18: 14 | C18: Sergio Molina | D18: Sergio Molina Beloqui | E18: Suplente (Banco) | F18: Titular Efetivo (44% min) | G18: Rodízio | H18: MC | I18: VOL, ZAG | J18: Meio-Campo | K18: 66 | L18: 66 | M18: =L18-K18 -> 0 | N18: =K18-66 -> 0 | O18: 29 | P18: 19/02/1996 | Q18: Espanha | R18: 975000 | S18: 3800 | T18: Sem multa rescisória | U18: 2028 | V18: Seguro (até 2028) | W18: =COUNTIFS('Desempenho por Jogo (Logs)'!$G$5:$G$206, A18) -> 10 | X18: =COUNTIFS('Desempenho por Jogo (Logs)'!$G$5:$G$206, A18, 'Desempenho por Jogo (Logs)'!$J$5:$J$206, "<>RES") -> 6 | Y18: =COUNTIFS('Desempenho por Jogo (Logs)'!$G$5:$G$206, A18, 'Desempenho por Jogo (Logs)'!$J$5:$J$206, "RES") -> 4 | Z18: =SUMIFS('Desempenho por Jogo (Logs)'!$K$5:$K$206, 'Desempenho por Jogo (Logs)'!$G$5:$G$206, A18) -> 514 | AA18: =IF(Z18>0, Z18/540, 0) -> 0.439 | AB18: =SUMIFS('Desempenho por Jogo (Logs)'!$L$5:$L$206, 'Desempenho por Jogo (Logs)'!$G$5:$G$206, A18) -> 3 | AC18: 0 | AD18: =AB18+AC18 -> 3 | AE18: =IF(Z18>0, ROUND((AD18/Z18)*90, 2), 0) -> 0.53 | AF18: =SUMIFS('Desempenho por Jogo (Logs)'!$L$5:$L$206, 'Desempenho por Jogo (Logs)'!$G$5:$G$206, A18, 'Desempenho por Jogo (Logs)'!$C$5:$C$206, "*Liga*") -> 3 | AG18: 0 | AH18: =SUMIFS('Desempenho por Jogo (Logs)'!$L$5:$L$206, 'Desempenho por Jogo (Logs)'!$G$5:$G$206, A18, 'Desempenho por Jogo (Logs)'!$C$5:$C$206, "*Trophy*") -> 0 | AI18: 0 | AJ18: 0 | AK18: =IFERROR(ROUND(AVERAGEIFS('Desempenho por Jogo (Logs)'!$N$5:$N$206, 'Desempenho por Jogo (Logs)'!$G$5:$G$206, A18, 'Desempenho por Jogo (Logs)'!$N$5:$N$206, ">0"), 2), "S/N") -> 7.16 | AL18: Boa (7,02) | AM18: =IF(W18=0, "Nula (0 jogos)", IF(OR(W18<=2, Z18<150), "Baixa — Amostra Insuficiente", IF(AND(W18>=4, Z18>=240), "Alta", "Moderada"))) -> Alta (≥4J e ≥270m) | AN18: =IF(W18=0, "Sem minutagem no save", IF(OR(W18<=2, Z18<150), "Amostra insuficiente (" & W18 & "J / " & Z18 & "m) — Continuar observando", IF(AK18>=7.5, "Promover minutos / Titularidade em ascensão", IF(AK18>=7.0, "Manter minutagem atual", "Avaliar opções / Rotação")))) -> Manter na Rotação do Elenco | AO18: Participação regular na rotação (514 min em 10J, OVR 66) | AP18: Atleta de 29 anos (Espanha). posição MC (VOL. ZAG). hierarquia atual 'Suplente (Banco)'. Overall 66 e Potencial 66 (margem de potencial +0; evolução real no save +0). Soma 514 min em 10 partidas (6T/4R). com 3 gol(s) verificado(s) por partida. 0 assistência(s) na temporada (3 G+A) e nota média 7.16. Vínculo: contrato até 2028 (Rodízio). avaliado em € 975.000.
A19: 279603 | B19: 15 | C19: Aingeru Olabarrieta | D19: Aingeru Olabarrieta Capelo | E19: Suplente (Banco) | F19: Titular Efetivo (40% min) | G19: Rodízio | H19: PD | I19: MD | J19: Ataque | K19: 69 | L19: 81 | M19: =L19-K19 -> 12 | N19: =K19-67 -> 2 | O19: 19 | P19: 15/11/2005 | Q19: Espanha | R19: 2900000 | S19: 3300 | T19: Emprestado (Sem multa) | U19: 2029 | V19: Empréstimo até Jun/2026 | W19: =COUNTIFS('Desempenho por Jogo (Logs)'!$G$5:$G$206, A19) -> 9 | X19: =COUNTIFS('Desempenho por Jogo (Logs)'!$G$5:$G$206, A19, 'Desempenho por Jogo (Logs)'!$J$5:$J$206, "<>RES") -> 6 | Y19: =COUNTIFS('Desempenho por Jogo (Logs)'!$G$5:$G$206, A19, 'Desempenho por Jogo (Logs)'!$J$5:$J$206, "RES") -> 3 | Z19: =SUMIFS('Desempenho por Jogo (Logs)'!$K$5:$K$206, 'Desempenho por Jogo (Logs)'!$G$5:$G$206, A19) -> 467 | AA19: =IF(Z19>0, Z19/540, 0) -> 0.399 | AB19: =SUMIFS('Desempenho por Jogo (Logs)'!$L$5:$L$206, 'Desempenho por Jogo (Logs)'!$G$5:$G$206, A19) -> 1 | AC19: 3 | AD19: =AB19+AC19 -> 4 | AE19: =IF(Z19>0, ROUND((AD19/Z19)*90, 2), 0) -> 0.77 | AF19: =SUMIFS('Desempenho por Jogo (Logs)'!$L$5:$L$206, 'Desempenho por Jogo (Logs)'!$G$5:$G$206, A19, 'Desempenho por Jogo (Logs)'!$C$5:$C$206, "*Liga*") -> 1 | AG19: 2 | AH19: =SUMIFS('Desempenho por Jogo (Logs)'!$L$5:$L$206, 'Desempenho por Jogo (Logs)'!$G$5:$G$206, A19, 'Desempenho por Jogo (Logs)'!$C$5:$C$206, "*Trophy*") -> 0 | AI19: 1 | AJ19: 1 | AK19: =IFERROR(ROUND(AVERAGEIFS('Desempenho por Jogo (Logs)'!$N$5:$N$206, 'Desempenho por Jogo (Logs)'!$G$5:$G$206, A19, 'Desempenho por Jogo (Logs)'!$N$5:$N$206, ">0"), 2), "S/N") -> 6.69 | AL19: Regular (6,78) | AM19: =IF(W19=0, "Nula (0 jogos)", IF(OR(W19<=2, Z19<150), "Baixa — Amostra Insuficiente", IF(AND(W19>=4, Z19>=240), "Alta", "Moderada"))) -> Alta (≥4J e ≥270m) | AN19: =IF(W19=0, "Sem minutagem no save", IF(OR(W19<=2, Z19<150), "Amostra insuficiente (" & W19 & "J / " & Z19 & "m) — Continuar observando", IF(AK19>=7.5, "Promover minutos / Titularidade em ascensão", IF(AK19>=7.0, "Manter minutagem atual", "Avaliar opções / Rotação")))) -> Jovem em Desenvolvimento Ativo — Manter Minutagem | AO19: 19 anos, POT 81 (+12 margem) e 467 min disputados (9J) | AP19: Atleta de 19 anos (Espanha). posição PD (MD). hierarquia atual 'Suplente (Banco)'. Overall 69 e Potencial 81 (margem de potencial +12; evolução real no save +2). Soma 467 min em 9 partidas (6T/3R). com 1 gol(s) verificado(s) por partida. 3 assistência(s) na temporada (4 G+A) e nota média 6.69. Vínculo: atleta emprestado ao clube até 2026. avaliado em € 2.900.000.
A20: 241505 | B20: 17 | C20: Thomas Carrique | D20: Thomas Carrique | E20: Suplente (Banco) | F20: Titular Efetivo (50% min) | G20: Rodízio | H20: LD | I20: MD | J20: Defesa | K20: 67 | L20: 67 | M20: =L20-K20 -> 0 | N20: =K20-66 -> 1 | O20: 26 | P20: 27/02/1999 | Q20: França | R20: 1100000 | S20: 3500 | T20: € 1.800.000 | U20: 2027 | V20: Atenção: Expira em 2027 (2 anos) | W20: =COUNTIFS('Desempenho por Jogo (Logs)'!$G$5:$G$206, A20) -> 10 | X20: =COUNTIFS('Desempenho por Jogo (Logs)'!$G$5:$G$206, A20, 'Desempenho por Jogo (Logs)'!$J$5:$J$206, "<>RES") -> 8 | Y20: =COUNTIFS('Desempenho por Jogo (Logs)'!$G$5:$G$206, A20, 'Desempenho por Jogo (Logs)'!$J$5:$J$206, "RES") -> 2 | Z20: =SUMIFS('Desempenho por Jogo (Logs)'!$K$5:$K$206, 'Desempenho por Jogo (Logs)'!$G$5:$G$206, A20) -> 581 | AA20: =IF(Z20>0, Z20/540, 0) -> 0.497 | AB20: =SUMIFS('Desempenho por Jogo (Logs)'!$L$5:$L$206, 'Desempenho por Jogo (Logs)'!$G$5:$G$206, A20) -> 0 | AC20: 2 | AD20: =AB20+AC20 -> 2 | AE20: =IF(Z20>0, ROUND((AD20/Z20)*90, 2), 0) -> 0.31 | AF20: =SUMIFS('Desempenho por Jogo (Logs)'!$L$5:$L$206, 'Desempenho por Jogo (Logs)'!$G$5:$G$206, A20, 'Desempenho por Jogo (Logs)'!$C$5:$C$206, "*Liga*") -> 0 | AG20: 2 | AH20: =SUMIFS('Desempenho por Jogo (Logs)'!$L$5:$L$206, 'Desempenho por Jogo (Logs)'!$G$5:$G$206, A20, 'Desempenho por Jogo (Logs)'!$C$5:$C$206, "*Trophy*") -> 0 | AI20: 0 | AJ20: 0 | AK20: =IFERROR(ROUND(AVERAGEIFS('Desempenho por Jogo (Logs)'!$N$5:$N$206, 'Desempenho por Jogo (Logs)'!$G$5:$G$206, A20, 'Desempenho por Jogo (Logs)'!$N$5:$N$206, ">0"), 2), "S/N") -> 6.72 | AL20: Regular (6,90) | AM20: =IF(W20=0, "Nula (0 jogos)", IF(OR(W20<=2, Z20<150), "Baixa — Amostra Insuficiente", IF(AND(W20>=4, Z20>=240), "Alta", "Moderada"))) -> Alta (≥4J e ≥270m) | AN20: =IF(W20=0, "Sem minutagem no save", IF(OR(W20<=2, Z20<150), "Amostra insuficiente (" & W20 & "J / " & Z20 & "m) — Continuar observando", IF(AK20>=7.5, "Promover minutos / Titularidade em ascensão", IF(AK20>=7.0, "Manter minutagem atual", "Avaliar opções / Rotação")))) -> Manter na Rotação do Elenco | AO20: Participação regular na rotação (581 min em 10J, OVR 67) | AP20: Atleta de 26 anos (França). posição LD (MD). hierarquia atual 'Suplente (Banco)'. Overall 67 e Potencial 67 (margem de potencial +0; evolução real no save +1). Soma 581 min em 10 partidas (8T/2R). com 0 gol(s) verificado(s) por partida. 2 assistência(s) na temporada (2 G+A) e nota média 6.72. Vínculo: contrato até 2027 (Rodízio). avaliado em € 1.100.000.
A21: 245704 | B21: 20 | C21: Martí Vilà | D21: Martí Vilà García | E21: Suplente (Banco) | F21: Titular Efetivo (47% min) | G21: Rodízio | H21: LE | I21: ZAG, ME | J21: Defesa | K21: 67 | L21: 67 | M21: =L21-K21 -> 0 | N21: =K21-66 -> 1 | O21: 26 | P21: 25/05/1999 | Q21: Espanha | R21: 1100000 | S21: 3500 | T21: Sem multa rescisória | U21: 2028 | V21: Seguro (até 2028) | W21: =COUNTIFS('Desempenho por Jogo (Logs)'!$G$5:$G$206, A21) -> 11 | X21: =COUNTIFS('Desempenho por Jogo (Logs)'!$G$5:$G$206, A21, 'Desempenho por Jogo (Logs)'!$J$5:$J$206, "<>RES") -> 7 | Y21: =COUNTIFS('Desempenho por Jogo (Logs)'!$G$5:$G$206, A21, 'Desempenho por Jogo (Logs)'!$J$5:$J$206, "RES") -> 4 | Z21: =SUMIFS('Desempenho por Jogo (Logs)'!$K$5:$K$206, 'Desempenho por Jogo (Logs)'!$G$5:$G$206, A21) -> 555 | AA21: =IF(Z21>0, Z21/540, 0) -> 0.474 | AB21: =SUMIFS('Desempenho por Jogo (Logs)'!$L$5:$L$206, 'Desempenho por Jogo (Logs)'!$G$5:$G$206, A21) -> 0 | AC21: 0 | AD21: =AB21+AC21 -> 0 | AE21: =IF(Z21>0, ROUND((AD21/Z21)*90, 2), 0) -> 0 | AF21: =SUMIFS('Desempenho por Jogo (Logs)'!$L$5:$L$206, 'Desempenho por Jogo (Logs)'!$G$5:$G$206, A21, 'Desempenho por Jogo (Logs)'!$C$5:$C$206, "*Liga*") -> 0 | AG21: 0 | AH21: =SUMIFS('Desempenho por Jogo (Logs)'!$L$5:$L$206, 'Desempenho por Jogo (Logs)'!$G$5:$G$206, A21, 'Desempenho por Jogo (Logs)'!$C$5:$C$206, "*Trophy*") -> 0 | AI21: 0 | AJ21: 0 | AK21: =IFERROR(ROUND(AVERAGEIFS('Desempenho por Jogo (Logs)'!$N$5:$N$206, 'Desempenho por Jogo (Logs)'!$G$5:$G$206, A21, 'Desempenho por Jogo (Logs)'!$N$5:$N$206, ">0"), 2), "S/N") -> 6.39 | AL21: Oscilante (6,34) | AM21: =IF(W21=0, "Nula (0 jogos)", IF(OR(W21<=2, Z21<150), "Baixa — Amostra Insuficiente", IF(AND(W21>=4, Z21>=240), "Alta", "Moderada"))) -> Alta (≥4J e ≥270m) | AN21: =IF(W21=0, "Sem minutagem no save", IF(OR(W21<=2, Z21<150), "Amostra insuficiente (" & W21 & "J / " & Z21 & "m) — Continuar observando", IF(AK21>=7.5, "Promover minutos / Titularidade em ascensão", IF(AK21>=7.0, "Manter minutagem atual", "Avaliar opções / Rotação")))) -> Manter na Rotação do Elenco | AO21: Participação regular na rotação (555 min em 11J, OVR 67) | AP21: Atleta de 26 anos (Espanha). posição LE (ZAG. ME). hierarquia atual 'Suplente (Banco)'. Overall 67 e Potencial 67 (margem de potencial +0; evolução real no save +1). Soma 555 min em 11 partidas (7T/4R). com 0 gol(s) verificado(s) por partida. 0 assistência(s) na temporada (0 G+A) e nota média 6.39. Vínculo: contrato até 2028 (Rodízio). avaliado em € 1.100.000.
A22: 75437 | B22: 29 | C22: Kim Min Su | D22: Min Su Kim | E22: Suplente (Banco) | F22: Titular Efetivo (40% min) | G22: Rodízio | H22: PE | I22: ME | J22: Ataque | K22: 71 | L22: 82 | M22: =L22-K22 -> 11 | N22: =K22-70 -> 1 | O22: 19 | P22: 20/01/2006 | Q22: Coreia do Sul | R22: 4500000 | S22: 4700 | T22: Emprestado (Sem multa) | U22: 2027 | V22: Empréstimo até Jun/2026 | W22: =COUNTIFS('Desempenho por Jogo (Logs)'!$G$5:$G$206, A22) -> 10 | X22: =COUNTIFS('Desempenho por Jogo (Logs)'!$G$5:$G$206, A22, 'Desempenho por Jogo (Logs)'!$J$5:$J$206, "<>RES") -> 7 | Y22: =COUNTIFS('Desempenho por Jogo (Logs)'!$G$5:$G$206, A22, 'Desempenho por Jogo (Logs)'!$J$5:$J$206, "RES") -> 3 | Z22: =SUMIFS('Desempenho por Jogo (Logs)'!$K$5:$K$206, 'Desempenho por Jogo (Logs)'!$G$5:$G$206, A22) -> 462 | AA22: =IF(Z22>0, Z22/540, 0) -> 0.395 | AB22: =SUMIFS('Desempenho por Jogo (Logs)'!$L$5:$L$206, 'Desempenho por Jogo (Logs)'!$G$5:$G$206, A22) -> 1 | AC22: 1 | AD22: =AB22+AC22 -> 2 | AE22: =IF(Z22>0, ROUND((AD22/Z22)*90, 2), 0) -> 0.39 | AF22: =SUMIFS('Desempenho por Jogo (Logs)'!$L$5:$L$206, 'Desempenho por Jogo (Logs)'!$G$5:$G$206, A22, 'Desempenho por Jogo (Logs)'!$C$5:$C$206, "*Liga*") -> 1 | AG22: 1 | AH22: =SUMIFS('Desempenho por Jogo (Logs)'!$L$5:$L$206, 'Desempenho por Jogo (Logs)'!$G$5:$G$206, A22, 'Desempenho por Jogo (Logs)'!$C$5:$C$206, "*Trophy*") -> 0 | AI22: 0 | AJ22: 0 | AK22: =IFERROR(ROUND(AVERAGEIFS('Desempenho por Jogo (Logs)'!$N$5:$N$206, 'Desempenho por Jogo (Logs)'!$G$5:$G$206, A22, 'Desempenho por Jogo (Logs)'!$N$5:$N$206, ">0"), 2), "S/N") -> 6.68 | AL22: Regular (6,58) | AM22: =IF(W22=0, "Nula (0 jogos)", IF(OR(W22<=2, Z22<150), "Baixa — Amostra Insuficiente", IF(AND(W22>=4, Z22>=240), "Alta", "Moderada"))) -> Alta (≥4J e ≥270m) | AN22: =IF(W22=0, "Sem minutagem no save", IF(OR(W22<=2, Z22<150), "Amostra insuficiente (" & W22 & "J / " & Z22 & "m) — Continuar observando", IF(AK22>=7.5, "Promover minutos / Titularidade em ascensão", IF(AK22>=7.0, "Manter minutagem atual", "Avaliar opções / Rotação")))) -> Jovem em Desenvolvimento Ativo — Manter Minutagem | AO22: 19 anos, POT 82 (+11 margem) e 462 min disputados (10J) | AP22: Atleta de 19 anos (Coreia do Sul). posição PE (ME). hierarquia atual 'Suplente (Banco)'. Overall 71 e Potencial 82 (margem de potencial +11; evolução real no save +1). Soma 462 min em 10 partidas (7T/3R). com 1 gol(s) verificado(s) por partida. 1 assistência(s) na temporada (2 G+A) e nota média 6.68. Vínculo: atleta emprestado ao clube até 2026. avaliado em € 4.500.000.
A23: 274828 | B23: 7 | C23: Álex Calvo | D23: Alejandro Calvo Mata | E23: Reserva (Não Relacionado) | F23: Rotação Ativa (24% min) | G23: Rodízio | H23: PD | I23: MD | J23: Ataque | K23: 67 | L23: 72 | M23: =L23-K23 -> 5 | N23: =K23-66 -> 1 | O23: 21 | P23: 21/02/2004 | Q23: Espanha | R23: 1600000 | S23: 2900 | T23: € 2.800.000 | U23: 2028 | V23: Seguro (até 2028) | W23: =COUNTIFS('Desempenho por Jogo (Logs)'!$G$5:$G$206, A23) -> 5 | X23: =COUNTIFS('Desempenho por Jogo (Logs)'!$G$5:$G$206, A23, 'Desempenho por Jogo (Logs)'!$J$5:$J$206, "<>RES") -> 4 | Y23: =COUNTIFS('Desempenho por Jogo (Logs)'!$G$5:$G$206, A23, 'Desempenho por Jogo (Logs)'!$J$5:$J$206, "RES") -> 1 | Z23: =SUMIFS('Desempenho por Jogo (Logs)'!$K$5:$K$206, 'Desempenho por Jogo (Logs)'!$G$5:$G$206, A23) -> 285 | AA23: =IF(Z23>0, Z23/540, 0) -> 0.244 | AB23: =SUMIFS('Desempenho por Jogo (Logs)'!$L$5:$L$206, 'Desempenho por Jogo (Logs)'!$G$5:$G$206, A23) -> 0 | AC23: 1 | AD23: =AB23+AC23 -> 1 | AE23: =IF(Z23>0, ROUND((AD23/Z23)*90, 2), 0) -> 0.32 | AF23: =SUMIFS('Desempenho por Jogo (Logs)'!$L$5:$L$206, 'Desempenho por Jogo (Logs)'!$G$5:$G$206, A23, 'Desempenho por Jogo (Logs)'!$C$5:$C$206, "*Liga*") -> 0 | AG23: 1 | AH23: =SUMIFS('Desempenho por Jogo (Logs)'!$L$5:$L$206, 'Desempenho por Jogo (Logs)'!$G$5:$G$206, A23, 'Desempenho por Jogo (Logs)'!$C$5:$C$206, "*Trophy*") -> 0 | AI23: 0 | AJ23: 0 | AK23: =IFERROR(ROUND(AVERAGEIFS('Desempenho por Jogo (Logs)'!$N$5:$N$206, 'Desempenho por Jogo (Logs)'!$G$5:$G$206, A23, 'Desempenho por Jogo (Logs)'!$N$5:$N$206, ">0"), 2), "S/N") -> 6.66 | AL23: Regular (6,66) | AM23: =IF(W23=0, "Nula (0 jogos)", IF(OR(W23<=2, Z23<150), "Baixa — Amostra Insuficiente", IF(AND(W23>=4, Z23>=240), "Alta", "Moderada"))) -> Alta (≥4J e ≥270m) | AN23: =IF(W23=0, "Sem minutagem no save", IF(OR(W23<=2, Z23<150), "Amostra insuficiente (" & W23 & "J / " & Z23 & "m) — Continuar observando", IF(AK23>=7.5, "Promover minutos / Titularidade em ascensão", IF(AK23>=7.0, "Manter minutagem atual", "Avaliar opções / Rotação")))) -> Manter na Rotação do Elenco | AO23: Participação regular na rotação (285 min em 5J, OVR 67) | AP23: Atleta de 21 anos (Espanha). posição PD (MD). hierarquia atual 'Reserva (Não Relacionado)'. Overall 67 e Potencial 72 (margem de potencial +5; evolução real no save +1). Soma 285 min em 5 partidas (4T/1R). com 0 gol(s) verificado(s) por partida. 1 assistência(s) na temporada (1 G+A) e nota média 6.66. Vínculo: contrato até 2028 (Rodízio). avaliado em € 1.600.000.
A24: 277311 | B24: 10 | C24: Álvaro Martín | D24: Álvaro Martín | E24: Reserva (Não Relacionado) | F24: Rotação Ativa (29% min) | G24: Rodízio | H24: MC | I24: MEI, VOL | J24: Meio-Campo | K24: 63 | L24: 68 | M24: =L24-K24 -> 5 | N24: =K24-63 -> 0 | O24: 24 | P24: 16/01/2001 | Q24: Espanha | R24: 850000 | S24: 2200 | T24: Sem multa rescisória | U24: 2030 | V24: Seguro (até 2030) | W24: =COUNTIFS('Desempenho por Jogo (Logs)'!$G$5:$G$206, A24) -> 5 | X24: =COUNTIFS('Desempenho por Jogo (Logs)'!$G$5:$G$206, A24, 'Desempenho por Jogo (Logs)'!$J$5:$J$206, "<>RES") -> 4 | Y24: =COUNTIFS('Desempenho por Jogo (Logs)'!$G$5:$G$206, A24, 'Desempenho por Jogo (Logs)'!$J$5:$J$206, "RES") -> 1 | Z24: =SUMIFS('Desempenho por Jogo (Logs)'!$K$5:$K$206, 'Desempenho por Jogo (Logs)'!$G$5:$G$206, A24) -> 343 | AA24: =IF(Z24>0, Z24/540, 0) -> 0.293 | AB24: =SUMIFS('Desempenho por Jogo (Logs)'!$L$5:$L$206, 'Desempenho por Jogo (Logs)'!$G$5:$G$206, A24) -> 0 | AC24: 0 | AD24: =AB24+AC24 -> 0 | AE24: =IF(Z24>0, ROUND((AD24/Z24)*90, 2), 0) -> 0 | AF24: =SUMIFS('Desempenho por Jogo (Logs)'!$L$5:$L$206, 'Desempenho por Jogo (Logs)'!$G$5:$G$206, A24, 'Desempenho por Jogo (Logs)'!$C$5:$C$206, "*Liga*") -> 0 | AG24: 0 | AH24: =SUMIFS('Desempenho por Jogo (Logs)'!$L$5:$L$206, 'Desempenho por Jogo (Logs)'!$G$5:$G$206, A24, 'Desempenho por Jogo (Logs)'!$C$5:$C$206, "*Trophy*") -> 0 | AI24: 0 | AJ24: 0 | AK24: =IFERROR(ROUND(AVERAGEIFS('Desempenho por Jogo (Logs)'!$N$5:$N$206, 'Desempenho por Jogo (Logs)'!$G$5:$G$206, A24, 'Desempenho por Jogo (Logs)'!$N$5:$N$206, ">0"), 2), "S/N") -> 6.7 | AL24: Regular (6,70) | AM24: =IF(W24=0, "Nula (0 jogos)", IF(OR(W24<=2, Z24<150), "Baixa — Amostra Insuficiente", IF(AND(W24>=4, Z24>=240), "Alta", "Moderada"))) -> Alta (≥4J e ≥270m) | AN24: =IF(W24=0, "Sem minutagem no save", IF(OR(W24<=2, Z24<150), "Amostra insuficiente (" & W24 & "J / " & Z24 & "m) — Continuar observando", IF(AK24>=7.5, "Promover minutos / Titularidade em ascensão", IF(AK24>=7.0, "Manter minutagem atual", "Avaliar opções / Rotação")))) -> Manter na Rotação do Elenco | AO24: Participação regular na rotação (343 min em 5J, OVR 63) | AP24: Atleta de 24 anos (Espanha). posição MC (MEI. VOL). hierarquia atual 'Reserva (Não Relacionado)'. Overall 63 e Potencial 68 (margem de potencial +5; evolução real no save +0). Soma 343 min em 5 partidas (4T/1R). com 0 gol(s) verificado(s) por partida. 0 assistência(s) na temporada (0 G+A) e nota média 6.70. Vínculo: contrato até 2030 (Rodízio). avaliado em € 850.000.
A25: 260044 | B25: 11 | C25: Lautaro de León | D25: Lautaro de León Billar | E25: Reserva (Não Relacionado) | F25: Titular Efetivo (46% min) | G25: Importante | H25: ATA | I25: — | J25: Ataque | K25: 68 | L25: 72 | M25: =L25-K25 -> 4 | N25: =K25-67 -> 1 | O25: 24 | P25: 10/02/2001 | Q25: Uruguai | R25: 1800000 | S25: 5000 | T25: € 4.000.000 | U25: 2028 | V25: Seguro (até 2028) | W25: =COUNTIFS('Desempenho por Jogo (Logs)'!$G$5:$G$206, A25) -> 7 | X25: =COUNTIFS('Desempenho por Jogo (Logs)'!$G$5:$G$206, A25, 'Desempenho por Jogo (Logs)'!$J$5:$J$206, "<>RES") -> 7 | Y25: =COUNTIFS('Desempenho por Jogo (Logs)'!$G$5:$G$206, A25, 'Desempenho por Jogo (Logs)'!$J$5:$J$206, "RES") -> 0 | Z25: =SUMIFS('Desempenho por Jogo (Logs)'!$K$5:$K$206, 'Desempenho por Jogo (Logs)'!$G$5:$G$206, A25) -> 534 | AA25: =IF(Z25>0, Z25/540, 0) -> 0.456 | AB25: =SUMIFS('Desempenho por Jogo (Logs)'!$L$5:$L$206, 'Desempenho por Jogo (Logs)'!$G$5:$G$206, A25) -> 5 | AC25: 0 | AD25: =AB25+AC25 -> 5 | AE25: =IF(Z25>0, ROUND((AD25/Z25)*90, 2), 0) -> 0.84 | AF25: =SUMIFS('Desempenho por Jogo (Logs)'!$L$5:$L$206, 'Desempenho por Jogo (Logs)'!$G$5:$G$206, A25, 'Desempenho por Jogo (Logs)'!$C$5:$C$206, "*Liga*") -> 2 | AG25: 0 | AH25: =SUMIFS('Desempenho por Jogo (Logs)'!$L$5:$L$206, 'Desempenho por Jogo (Logs)'!$G$5:$G$206, A25, 'Desempenho por Jogo (Logs)'!$C$5:$C$206, "*Trophy*") -> 3 | AI25: 0 | AJ25: 2 | AK25: =IFERROR(ROUND(AVERAGEIFS('Desempenho por Jogo (Logs)'!$N$5:$N$206, 'Desempenho por Jogo (Logs)'!$G$5:$G$206, A25, 'Desempenho por Jogo (Logs)'!$N$5:$N$206, ">0"), 2), "S/N") -> 7.11 | AL25: Regular (6,70) | AM25: =IF(W25=0, "Nula (0 jogos)", IF(OR(W25<=2, Z25<150), "Baixa — Amostra Insuficiente", IF(AND(W25>=4, Z25>=240), "Alta", "Moderada"))) -> Alta (≥4J e ≥270m) | AN25: =IF(W25=0, "Sem minutagem no save", IF(OR(W25<=2, Z25<150), "Amostra insuficiente (" & W25 & "J / " & Z25 & "m) — Continuar observando", IF(AK25>=7.5, "Promover minutos / Titularidade em ascensão", IF(AK25>=7.0, "Manter minutagem atual", "Avaliar opções / Rotação")))) -> Manter na Rotação do Elenco | AO25: Participação regular na rotação (534 min em 7J, OVR 68) | AP25: Atleta de 24 anos (Uruguai). posição ATA. hierarquia atual 'Reserva (Não Relacionado)'. Overall 68 e Potencial 72 (margem de potencial +4; evolução real no save +1). Soma 534 min em 7 partidas (7T/0R). com 5 gol(s) verificado(s) por partida. 0 assistência(s) na temporada (5 G+A) e nota média 7.11. Vínculo: contrato até 2028 (Importante). avaliado em € 1.800.000.
A26: 79752 | B26: 18 | C26: Marc Doménech | D26: Marc Doménech | E26: Reserva (Não Relacionado) | F26: Titular Efetivo (34% min) | G26: Rodízio | H26: MC | I26: VOL | J26: Meio-Campo | K26: 65 | L26: 71 | M26: =L26-K26 -> 6 | N26: =K26-64 -> 1 | O26: 22 | P26: 02/11/2002 | Q26: Espanha | R26: 1400000 | S26: 2400 | T26: Sem multa rescisória | U26: 2028 | V26: Seguro (até 2028) | W26: =COUNTIFS('Desempenho por Jogo (Logs)'!$G$5:$G$206, A26) -> 9 | X26: =COUNTIFS('Desempenho por Jogo (Logs)'!$G$5:$G$206, A26, 'Desempenho por Jogo (Logs)'!$J$5:$J$206, "<>RES") -> 4 | Y26: =COUNTIFS('Desempenho por Jogo (Logs)'!$G$5:$G$206, A26, 'Desempenho por Jogo (Logs)'!$J$5:$J$206, "RES") -> 5 | Z26: =SUMIFS('Desempenho por Jogo (Logs)'!$K$5:$K$206, 'Desempenho por Jogo (Logs)'!$G$5:$G$206, A26) -> 397 | AA26: =IF(Z26>0, Z26/540, 0) -> 0.339 | AB26: =SUMIFS('Desempenho por Jogo (Logs)'!$L$5:$L$206, 'Desempenho por Jogo (Logs)'!$G$5:$G$206, A26) -> 0 | AC26: 0 | AD26: =AB26+AC26 -> 0 | AE26: =IF(Z26>0, ROUND((AD26/Z26)*90, 2), 0) -> 0 | AF26: =SUMIFS('Desempenho por Jogo (Logs)'!$L$5:$L$206, 'Desempenho por Jogo (Logs)'!$G$5:$G$206, A26, 'Desempenho por Jogo (Logs)'!$C$5:$C$206, "*Liga*") -> 0 | AG26: 0 | AH26: =SUMIFS('Desempenho por Jogo (Logs)'!$L$5:$L$206, 'Desempenho por Jogo (Logs)'!$G$5:$G$206, A26, 'Desempenho por Jogo (Logs)'!$C$5:$C$206, "*Trophy*") -> 0 | AI26: 0 | AJ26: 1 | AK26: =IFERROR(ROUND(AVERAGEIFS('Desempenho por Jogo (Logs)'!$N$5:$N$206, 'Desempenho por Jogo (Logs)'!$G$5:$G$206, A26, 'Desempenho por Jogo (Logs)'!$N$5:$N$206, ">0"), 2), "S/N") -> 6.73 | AL26: Oscilante (6,42) | AM26: =IF(W26=0, "Nula (0 jogos)", IF(OR(W26<=2, Z26<150), "Baixa — Amostra Insuficiente", IF(AND(W26>=4, Z26>=240), "Alta", "Moderada"))) -> Alta (≥4J e ≥270m) | AN26: =IF(W26=0, "Sem minutagem no save", IF(OR(W26<=2, Z26<150), "Amostra insuficiente (" & W26 & "J / " & Z26 & "m) — Continuar observando", IF(AK26>=7.5, "Promover minutos / Titularidade em ascensão", IF(AK26>=7.0, "Manter minutagem atual", "Avaliar opções / Rotação")))) -> Manter na Rotação do Elenco | AO26: Participação regular na rotação (397 min em 9J, OVR 65) | AP26: Atleta de 22 anos (Espanha). posição MC (VOL). hierarquia atual 'Reserva (Não Relacionado)'. Overall 65 e Potencial 71 (margem de potencial +6; evolução real no save +1). Soma 397 min em 9 partidas (4T/5R). com 0 gol(s) verificado(s) por partida. 0 assistência(s) na temporada (0 G+A) e nota média 6.73. Vínculo: contrato até 2028 (Rodízio). avaliado em € 1.400.000.
A27: 228707 | B27: 23 | C27: Diego Alende | D27: Diego Alende López | E27: Reserva (Não Relacionado) | F27: Titular Efetivo (31% min) | G27: Rodízio | H27: ZAG | I27: — | J27: Defesa | K27: 67 | L27: 68 | M27: =L27-K27 -> 1 | N27: =K27-66 -> 1 | O27: 28 | P27: 26/08/1997 | Q27: Espanha | R27: 1100000 | S27: 3500 | T27: € 1.800.000 | U27: 2027 | V27: Atenção: Expira em 2027 (2 anos) | W27: =COUNTIFS('Desempenho por Jogo (Logs)'!$G$5:$G$206, A27) -> 4 | X27: =COUNTIFS('Desempenho por Jogo (Logs)'!$G$5:$G$206, A27, 'Desempenho por Jogo (Logs)'!$J$5:$J$206, "<>RES") -> 4 | Y27: =COUNTIFS('Desempenho por Jogo (Logs)'!$G$5:$G$206, A27, 'Desempenho por Jogo (Logs)'!$J$5:$J$206, "RES") -> 0 | Z27: =SUMIFS('Desempenho por Jogo (Logs)'!$K$5:$K$206, 'Desempenho por Jogo (Logs)'!$G$5:$G$206, A27) -> 360 | AA27: =IF(Z27>0, Z27/540, 0) -> 0.308 | AB27: =SUMIFS('Desempenho por Jogo (Logs)'!$L$5:$L$206, 'Desempenho por Jogo (Logs)'!$G$5:$G$206, A27) -> 0 | AC27: 0 | AD27: =AB27+AC27 -> 0 | AE27: =IF(Z27>0, ROUND((AD27/Z27)*90, 2), 0) -> 0 | AF27: =SUMIFS('Desempenho por Jogo (Logs)'!$L$5:$L$206, 'Desempenho por Jogo (Logs)'!$G$5:$G$206, A27, 'Desempenho por Jogo (Logs)'!$C$5:$C$206, "*Liga*") -> 0 | AG27: 0 | AH27: =SUMIFS('Desempenho por Jogo (Logs)'!$L$5:$L$206, 'Desempenho por Jogo (Logs)'!$G$5:$G$206, A27, 'Desempenho por Jogo (Logs)'!$C$5:$C$206, "*Trophy*") -> 0 | AI27: 0 | AJ27: 0 | AK27: =IFERROR(ROUND(AVERAGEIFS('Desempenho por Jogo (Logs)'!$N$5:$N$206, 'Desempenho por Jogo (Logs)'!$G$5:$G$206, A27, 'Desempenho por Jogo (Logs)'!$N$5:$N$206, ">0"), 2), "S/N") -> 7.3 | AL27: Boa (7,30) | AM27: =IF(W27=0, "Nula (0 jogos)", IF(OR(W27<=2, Z27<150), "Baixa — Amostra Insuficiente", IF(AND(W27>=4, Z27>=240), "Alta", "Moderada"))) -> Alta (≥4J e ≥270m) | AN27: =IF(W27=0, "Sem minutagem no save", IF(OR(W27<=2, Z27<150), "Amostra insuficiente (" & W27 & "J / " & Z27 & "m) — Continuar observando", IF(AK27>=7.5, "Promover minutos / Titularidade em ascensão", IF(AK27>=7.0, "Manter minutagem atual", "Avaliar opções / Rotação")))) -> Sugestão: Testar com Mais Minutos na Rotação | AO27: Suplente com boa produção em 4J / 360 min (Nota 7,30, 0 G+A); sugestão consultiva sem alterar escalação | AP27: Atleta de 28 anos (Espanha). posição ZAG. hierarquia atual 'Reserva (Não Relacionado)'. Overall 67 e Potencial 68 (margem de potencial +1; evolução real no save +1). Soma 360 min em 4 partidas (4T/0R). com 0 gol(s) verificado(s) por partida. 0 assistência(s) na temporada (0 G+A) e nota média 7.30. Vínculo: contrato até 2027 (Rodízio). avaliado em € 1.100.000.
